<!-- 设置机器底盘，并加上摄像头 -->
<robot name="mycar">
    <!-- 底盘link -->
    <link name="base_link">
        <visual>
            <geometry>
                <box size="0.3 0.2 0.1"/>
            </geometry>
            <origin xyz="0 0 0.0" rpy="0.0 0.0 0.0"/>
            <material name="car_color">
                <color rgba="0.0 0.0 1 0.5"/>
            </material>
        </visual>
    </link>
    <!-- 摄像link -->
    <link name="camera">
        <visual>
            <geometry>
                <box size="0.02 0.05 0.05"/>
            </geometry>
            <origin xyz="0 0 0.025" rpy="0 0.0 0"/>
            <material name="camera">
                <color rgba="1 0.0 0.0 0.5"/>
            </material>
        </visual>
    </link>
    <!-- 关节 -->
    <joint name="camera2base" type="continuous">
        <!-- 父link -->
        <parent link="base_link"/>
        <!-- 子link -->
        <child link="camera"/>
        <!-- 偏移两 -->
        <origin xyz="0.12 0.0 0.05" rpy="0.0 0.0 0.0"/>
        <!-- 关节旋转参考坐标轴 -->
        <axis xyz="0.0 0.0 1"/>
    </joint>
 
</robot>